<?xml version="1.0" encoding="UTF-8"?>
<testsuite name="com.dotcms.util.TestExceptionUtil" tests="4" skipped="0" failures="0" errors="0" timestamp="2023-07-14T17:44:31" hostname="fv-az487-488" time="0.003">
  <properties/>
  <testcase name="TestExceptionIsNotCausedBy" classname="com.dotcms.util.TestExceptionUtil" time="0.002"/>
  <testcase name="TestExceptionIsCausedBy" classname="com.dotcms.util.TestExceptionUtil" time="0.0"/>
  <testcase name="TestException_getCauseBy" classname="com.dotcms.util.TestExceptionUtil" time="0.001"/>
  <testcase name="TestExceptionIsCausedByMany" classname="com.dotcms.util.TestExceptionUtil" time="0.0"/>
  <system-out><![CDATA[]]></system-out>
  <system-err><![CDATA[]]></system-err>
</testsuite>
